Workbook
Name Slicer_Zone: #N/A

Sheet Qs)Part-3
A3: Count of Evaluation_ID | B3: Column Labels
A4: Row Labels | B4: Average Performer | C4: Bottom Performer | D4: High Performer | E4: Low Performer | F4: Grand Total
A5: East | B5: 0.14285714 | C5: 0.14285714 | D5: 0.28571429 | E5: 0.42857143 | F5: 1
A6: North | B6: 0.47368421 | C6: 0.052631579 | D6: 0.21052632 | E6: 0.26315789 | F6: 1
A7: South | B7: 0.38888889 | C7: 0.16666667 | D7: 0.11111111 | E7: 0.33333333 | F7: 1
A8: West | B8: 0.58823529 | C8: 0.17647059 | D8: 0.11764706 | E8: 0.11764706 | F8: 1
A9: Grand Total | B9: 0.44262295 | C9: 0.13114754 | D9: 0.16393443 | E9: 0.26229508 | F9: 1

Sheet Qs)Part-4 Visualizations-1
A1: Row Labels | B1: Average of Evaluation_Score
A2: East | B2: 71.571429
A3: North | B3: 76.736842
A4: South | B4: 66.611111
A5: West | B5: 71.823529
A6: Grand Total | B6: 71.786885

Sheet CX_Junior BI Analyst_Test
A1: Evaluation_ID | B1: Evaluation_Date | C1: Evaluation_Score | D1: STORE AMBIANCE | E1: FIRST IMPRESSIONS | F1: DISCOVERY | G1: RECOMMENDATIONS | H1: TRIAL EXPERIENCE & UPSELL | I1: OBJECTION HANDLING | J1: CLOSURE & CARE | K1: OVERALL EXPERIENCE | L1: Location_City | M1: Location_State | N1: Zone | O1: Location_Country | P1: Time of entry: | Q1: Time of exit: | R1: Duration of visit: | S1: How many Style Advisors were present in the store during your visit? | T1: How many customers were present in the store during your visit? | U1: Age of the Auditor: | V1: Gender of Auditor: | W1: Please describe what you were wearing during your visit. | X1: Name of the Style Advisor who attended to you: | Y1: Please provide a detailed physical description (gender, approx. height, complexion, hair colour, wore spectacles, wearing Company branded t-shirt, plain jeans, shoes, proper shave and hairstyle done, etc.) | Z1: 1.1 - Was the exterior signage clean and well lit? | AA1: 1.2 - Was the store threshold, entrance and overall look inviting? | AB1: 1.3 - Were all the fixtures and other tangibles in good condition (walls, lights, floor, etc.)? | AC1: 1.4 - Was there any music playing at the store? | AD1: 1.5 - Was the digital screen in the store operational during your visit? | AE1: 1.6 - Did you see any cartons, etc. lying around? | AF1: 1.7 - Was the merchandise displayed and arranged well on the drawers/shelves/display tables? | AG1: 1.8 - Was the merchandise arranged according to the brand and frame type? | AH1: 1.9 - Upon your entrance, did you feel welcomed to freely move and explore the store? | AI1: 1.10 - Additional remarks, if any. | AJ1: 2.1 - What was your first impression when you entered the store? Please mention the details. | AK1: 2.1.1 Please justify your reason for the above marking. | AL1: 2.2 - Were you acknowledged and greeted with the following: | AM1: 2.3 - How long did you have to wait to receive service from the Style Advisor (from the moment you entered the store until you received service from the advisor)? | AN1: 2.4 - Was the store temperature maintained at a comfortable level? | AO1: 2.5 - Was there a pleasant aroma inside the store? | AP1: 2.6 - Were the racks and signages for offers neat and clean, and was the cashier desk neat and well stocked? | AQ1: 2.7 - Were you proactively approached by the Style Advisor to initiate in an icebreaking, non transactional conversation? (Eg: "Nice shades/watch/denims!", "I must say you have great taste") | AR1: 2.8 - Were you given assistance with your bags, if you had any? (mark N/A if you did not have any bags) | AS1: 3.1 - Did Style Advisor proactively engage you in a conversation to understand your needs and wants? Questions may include occasion/reason for purchase, lifestyle, choice of colour, style, material, volume, function, size, etc. | AT1: 3.2 - Did Style Advisor genuinely show an interest in your needs and listen to you empathically? | AU1: 3.3 - What were the questions asked by the Style Advisor to discover your needs? | AV1: 3.4 - While presenting the product, did the Style Advisor tell you about the brand? | AW1: 3.5 - Additional remarks, if any. | AX1: 3.6 - When you stated your interest in a specific brand, did the Style Advisor respond by asking you questions about your product needs? | AY1: 3.6.1 - If yes, what were the questions asked pertaining to that brand? | AZ1: 4.1 - Were multiple options introduced across the brands as per your needs? | BA1: 4.2 - Did Style Advisor share the current season's inspiration or craftsmanship of the product? | BB1: 4.3 - While showing the options, did the Style Advisor talk about the characteristics of the product and how it will benefit you and meet your needs? (This may include the name of the product, their style, quality or type of material, comfort, etc.) | BC1: 4.4 - Did they briefly share the brand story with you? | BD1: 5.1 - Were you encouraged to touch/feel and try the products? | BE1: 5.2 - Did Style Advisor offer compliments/corrections post-trial? | BF1: 5.3 - Did the Style Advisor offer appropriate recommendations as per your facial characteristics and anatomy? | BG1: 5.4 - Did the Style Advisor clean the sunglasses before the trial? | BH1: 5.5 - Did the Style Advisor use the styling tray and microfiber cloth during the trial and demonstration? | BI1: 5.6 - Did the Style Advisor try to get your feedback as well as give suggestions about the products being shown and tried on? | BJ1: 5.7 - Did the Style Advisor try to up-sell products from different categories? (Recommend product eg New arrivals, festive collections etc)? | BK1: 5.8 - Please mention the details of the product recommended. | BL1: 5.9 - Please share your overall trial experience. | BM1: 6.1 - What objection did you raise during the visit for the recommended product/brand? | BN1: 6.1.1 - If other, please elaborate | BO1: 6.2 - If you raised an objection on a product, did the Style Advisor make an effort to understand the reason for your hesitation? | BP1: 6.3 - Did the Style Advisor answer your objection appropriately and address the concern that you brought up? | BQ1: 6.4 - Did the Style Advisor show you any other product to match your need? | BR1: 7.1 - At the end of the interaction, did the Style Advisor do any of the following? | BS1: 7.1.1 - If other, please specify. | BT1: 7.2 - Did the Style Advisor try to close the sale in a pleasant and positive manner? | BU1: 7.3 - Did the Style Advisor talk about the ongoing offers during the conversation? | BV1: 7.4 - Did the Style Advisor talk about the "Sun Perks" loyalty program? | BW1: 7.5 - Did the Style Advisor talk about the benefits of "Perfect Pair Promise"? | BX1: 7.6 - Did the Style Advisor's attitude change when he/she realized that you would not be buying the product on the same day? | BY1: 7.7 - Did Style Advisor share a reason to come back (possibly including dates for an upcoming collection, any events or offers)? | BZ1: 7.8 - Did the Style Advisor thank you for visiting the store? | CA1: 7.9 - Did Style Advisor accompany you to the exit, bid you farewell in warm manner, and invite you to come back? | CB1: 8.1 - On a scale of 1 to 10, how likely is it that you will come back to the Sunglass Hut? | CC1: 8.2 - Did you find Style Advisor engaging & displaying positive body language during entire conversation? | CD1: 8.3 - On a scale of 1 to 10, rate the Style Advisor on his/her overall assistance during the visit.
A2: 11078689 | B2: 2022-10-01 | C2: 58 | D2: 100 | E2: 56 | F2: 80 | G2: 17 | H2: 50 | I2: 0 | J2: 57 | K2: 100 | L2: Delhi | M2: Delhi (UT) | N2: North | O2: IN | P2: 12:25 | Q2: 12:42 | R2: 1020 | S2: 2 | T2: 5 | U2: 23 | V2: Male | W2: I was wearing a formal shirt and trousers. | X2: Kamal | Y2: Male, approximately 5'10' in height, black hair, wore no spectacles and was wearing an orange coloured branded t-shirt, blue jeansY2:Y61 with casual shoes, clean-shaven and was wearing a mask. | Z2: Yes | AA2: Yes | AB2: Yes | AC2: Yes | AD2: Yes | AE2: No | AF2: Yes | AG2: Yes | AH2: Yes | AI2: The store had a completely wide entrance which made it overall look very appealing. All the sunglasses were arranged correctly with the brand tags. The store was well-lit and did not have any fuse bulbs. The display screens were working and had marketing running for Sunglass Hut. No cartons were seen in the store. Overall, the entire look and feel of the store were very good and I was able to access it freely and explore the same. | AJ2: WOW! Very appealing | AL2: Smile^Eye contact | AM2: After 2 minutes | AN2: Yes | AO2: Yes | AP2: Yes | AQ2: No | AR2: N/A | AS2: Yes | AT2: Yes | AU2: As I mentioned that I was looking for sunglasses for daily wear, the style advisor asked for my preference for sunglasses. I was asked whether I would prefer an aviator or wayfarer or any other style. He also asked if I was looking for any particular brand to which I mentioned that I was open to suggestions and not looking for any specific brand. | AV2: Yes | AW2: The style advisor informed me about the brand name while showing the sunglasses. | AX2: No | AZ2: Yes | BA2: No | BB2: No | BC2: No | BD2: Yes | BE2: No | BF2: Yes | BG2: No | BH2: No | BI2: Yes | BJ2: No | BK2: The products recommended by the style advisor were Aviator from Ray-Ban, Wayfarer from Ray-Ban, Wayfarer from Dolce & Gabbana, and Giorgio Armani. | BL2: The store was busy with 5 customers and only 2 style advisors. Hence, the style advisor was not able to provide complete attention to any customer considering the rush. They were assisting multiple customers in one go. He showed me 3 sunglasses and offered to try them but did not clean them before the trial. When I told him to have a look over more sunglasses, he offered one from Giorgio Armani. After the trial, he confirmed if I liked the same. However, he did not give any remarks on the look from his end. He did not use the styling tray and microfiber cloth during the trial and demonstration. He did not recommend any additional product. | BM2: Discount on the first pair | BO2: No | BP2: No | BQ2: No | BR2: Gave information about the price, payment options | BT2: Yes | BU2: Yes | BV2: No | BW2: No | BX2: No | BY2: N/A | BZ2: Yes | CA2: No | CB2: 8 | CC2: Yes | CD2: 7
A3: 11083235 | B3: 2022-10-08 | C3: 86 | D3: 100 | E3: 100 | F3: 100 | G3: 67 | H3: 75 | I3: 100 | J3: 63 | K3: 100 | L3: Ahmedabad | M3: Gujarat | N3: West | O3: IN | P3: 14:43 | Q3: 15:05 | R3: 1320 | S3: 2 | T3: 3 | U3: 35 | V3: Male | W3: I was wearing a white shirt with blue strips along with blue jeans and casual shoes. | X3: Sanket Patel | Y3: Male, approximately 5'8'' in height, wheatish complexion, black hair, was wearing spectacles, wore the Company branded t-shirt, plain light blue jeans, closed shoes, properly shaved and hairstyle was done in a proper manner. | Z3: Yes | AA3: Yes | AB3: Yes | AC3: Yes | AD3: Yes | AE3: No | AF3: Yes | AG3: Yes | AH3: Yes | AI3: The store exterior signage was clean and well-lit. The store threshold and entrance were looking inviting to customers. All the fixtures, walls, floor, and lights in the store were in good condition. There was light background music playing in the store. There was a digital screen kept outside the store in a proper manner. There were no cartons found lying on the floor in the store. The merchandise was displayed and arranged well on the shelves and display tables. All the merchandise was arranged according to the brand and frame type. At the entrance, I did feel welcomed and the style advisor allowed me to freely move around to explore the store. | AJ3: Good, looks interesting | AL3: Smile^Eye contact^Verbal greeting within 15 seconds | AM3: Within 2 minutes | AN3: Yes | AO3: Yes | AP3: Yes | AQ3: Yes | AR3: N/A | AS3: Yes | AT3: Yes | AU3: The style advisor tried to find my needs by asking which brand I would prefer and if there was any specific style or shape of sunglasses that I was looking for. | AV3: Yes | AW3: The style advisor mentioned the brand like Burberry brand which was a British fashion brand that provided a two-year international warranty. For the Prada brand, the style advisor mentioned that they had two different categories like Prada style and Prada sportswear collection. The style advisor informed me that Prada sunglasses were made in Italy and offered a two-year international warranty. | AX3: Yes | AY3: On showing my interest in the Prada brand of sunglasses, the style advisor tried to find which type, shape, and color shade I would prefer on the sunglasses that I was looking for. The style advisor showcased a couple of options in the Prada brand of sunglasses and offered to try them along with complimenting the looks in a positive manner. | AZ3: Yes | BA3: No | BB3: Yes | BC3: Yes | BD3: Yes | BE3: Yes | BF3: Yes | BG3: Yes | BH3: No | BI3: Yes | BJ3: No | BK3: The style advisor offered different brands like Ray-Ban, Burberry, Prada, and Emporio Armani. The style advisor mentioned the brand like Burberry brand which was a British fashion brand that provided a two-year international warranty. For the Prada brand, the style advisor mentioned that they had two different categories like Prada style and Prada sportswear collection. The style advisor informed me that Prada sunglasses were made in Italy and offered a two-year international warranty. The style advisor showcased the products according to my preference like style, shape, and comfort. | BL3: The style advisor encouraged me to touch and try the products. The style advisor complimented the tried products and offered suggestions looking at my face look. The style advisor cleaned the sunglasses before offering a trial using a microfiber cloth, but there was no styling tray used during the visit. The feedback about the shape and fitting of the sunglasses was captured by the style advisor during the trial. No additional product was offered by the style advisor to complete the look. | BM3: Discount on the first pair | BO3: Yes | BP3: Yes | BQ3: Yes | BR3: Asked if you were ready to purchase today^Offered information on another product to help you decide^Gave information about the price, payment options | BT3: Yes | BU3: Yes | BV3: No | BW3: No | BX3: Yes | BY3: Yes | BZ3: Yes | CA3: Yes | CB3: 8 | CC3: Yes | CD3: 8
A4: 11083324 | B4: 2022-10-14 | C4: 72 | D4: 100 | E4: 100 | F4: 80 | G4: 17 | H4: 75 | I4: 100 | J4: 25 | K4: 100 | L4: Gurgoan | M4: Haryana | N4: North | O4: IN | P4: 12:59 | Q4: 13:17 | R4: 1080 | S4: 3 | T4: 4 | U4: 34 | V4: Male | W4: I was wearing a yellow t-shirt with jeans. | X4: Mahesh | Y4: Male, approximately 5'5' in height, medium build with black hair, and was wearing a branded t-shirt with jeans. | Z4: Yes | AA4: Yes | AB4: Yes | AC4: Yes | AD4: Yes | AE4: No | AF4: Yes | AG4: Yes | AH4: Yes | AI4: The store's ambiance was good and all the lights were working properly. The store looked clean and neat with all the displays arranged properly. The style advisors welcomed the customers properly. | AJ4: WOW! Very appealing | AL4: Smile^Eye contact^Verbal greeting within 15 seconds | AM4: Within 2 minutes | AN4: Yes | AO4: Yes | AP4: Yes | AQ4: Yes | AR4: Yes | AS4: Yes | AT4: Yes | AU4: The style advisor understood my needs properly and asked what I was looking for and whether I was looking for men's or women's sunglasses. | AV4: Yes | AW4: When I showed an interest in Rayban and Bvlgari brands, he showed me various collections from both brands and informed me of their 2-year international warranty. | AX4: No | AZ4: Yes | BA4: No | BB4: No | BC4: No | BD4: Yes | BE4: Yes | BF4: Yes | BG4: Yes | BH4: Yes | BI4: No | BJ4: No | BK4: The style advisor recommended Rayban and Bvlgari sunglasses and told me of their offers and schemes. | BL4: The trial experience was good. He gave me appropriate compliments based on how all the products made me look. He showed me all the models that I had wanted to look at and try. Before the trial, he cleaned all the glasses. No feedback was taken. No additional products were mentioned. | BM4: Expensive products | BO4: Yes | BP4: Yes | BQ4: Yes | BR4: Offered information on another product to help you decide | BT4: Yes | BU4: Yes | BV4: No | BW4: No | BX4: Yes | BY4: No | BZ4: No | CA4: No | CB4: 7 | CC4: Yes | CD4: 8
A5: 11083483 | B5: 2022-10-06 | C5: 84 | D5: 89 | E5: 80 | F5: 80 | G5: 100 | H5: 63 | I5: 100 | J5: 88 | K5: 100 | L5: Jaipur | M5: Rajasthan | N5: North | O5: IN | P5: 15:35 | Q5: 16:06 | R5: 1860 | S5: 2 | T5: 1 | U5: 28 | V5: Male | W5: I was wearing a black shirt with pants. | X5: Sonali | Y5: Female, approximately 5ft in height, fair complexion with medium-length black hair, sdid not wear spectacles and was wearing an orange t-shirt, in her 20s, medium build. | Z5: Yes | AA5: Yes | AB5: Yes | AC5: No | AD5: Yes | AE5: No | AF5: Yes | AG5: Yes | AH5: Yes | AI5: The exterior signage of the outlet was clean and well-lit. The fixtures and other tangibles were in good condition. Music was not played. There was a digital screen outside the store which was operational and there were no cartons lying around the store. The style advisor immediately greeted me as soon as I entered the outlet. | AJ5: WOW! Very appealing | AL5: Smile^Eye contact^Verbal greeting within 15 seconds | AM5: Within 2 minutes | AN5: Yes | AO5: Yes | AP5: Yes | AQ5: No | AR5: No | AS5: Yes | AT5: Yes | AU5: The style advisor asked about my profession and asked whether I was looking at the glasses for myself or for my family members. | AV5: Yes | AW5: N/A | AX5: No | AZ5: Yes | BA5: Yes | BB5: Yes | BC5: Yes | BD5: Yes | BE5: Yes | BF5: Yes | BG5: No | BH5: No | BI5: No | BJ5: Yes | BK5: The style advisor recommended glasses from brands like Versace, Prada, Burberry, Ray-Ban, etc. | BL5: The trial experience could have been more effective had the style advisor helped clean the glasses before the trial but the style advisor did not do so and did not use the styling tray as well. During the trial, the style advisor tried to upsell the products but did not try to get my feedback. | BM5: Expensive products | BO5: Yes | BP5: Yes | BQ5: Yes | BR5: Asked if you were ready to purchase today^Offered information on another product to help you decide^Summarized your needs and matched them to the product recommended^Asked if you had any further questions | BT5: Yes | BU5: Yes | BV5: Yes | BW5: No | BX5: No | BY5: Yes | BZ5: Yes | CA5: Yes | CB5: 10 | CC5: Yes | CD5: 8
A6: 11083490 | B6: 2022-10-18 | C6: 84 | D6: 89 | E6: 80 | F6: 80 | G6: 100 | H6: 63 | I6: 100 | J6: 88 | K6: 100 | L6: Udaipur | M6: Rajasthan | N6: North | O6: IN | P6: 13:55 | Q6: 14:30 | R6: 2100 | S6: 1 | T6: 1 | U6: 28 | V6: Male | W6: I was wearing a grey formal shirt with pants. | X6: Jateen | Y6: Male, approximately 5'5' in height, wheatish complexion, black short hair, did not wear spectacles and was wearing an orange t-shirt, in his 20s, medium build. | Z6: Yes | AA6: Yes | AB6: Yes | AC6: No | AD6: Yes | AE6: No | AF6: Yes | AG6: Yes | AH6: Yes | AI6: The exterior signage of the outlet was clean and well-lit. The fixtures and other tangibles were in good condition. Music was not played. There was no digital screen outside the outlet and there were no cartons lying around. The style advisor immediately greeted me as soon as I entered the store. | AJ6: WOW! Very appealing | AL6: Smile^Eye contact^Verbal greeting within 15 seconds | AM6: Within 2 minutes | AN6: Yes | AO6: Yes | AP6: Yes | AQ6: No | AR6: No | AS6: Yes | AT6: Yes | AU6: The style advisor asked about my profession and also asked if I was looking at the glasses for myself or for my family members. | AV6: Yes | AW6: No additional remarks were made. | AX6: No | AZ6: Yes | BA6: Yes | BB6: Yes | BC6: Yes | BD6: Yes | BE6: No | BF6: Yes | BG6: Yes | BH6: No | BI6: No | BJ6: Yes | BK6: The style advisor recommended sunglasses from the brands like Versace, Prada, Burberry, Ray-Ban, etc. | BL6: The trial experience could have been more effective if the style advisor had used the styling tray and the micro-fiber cloth to clean the glasses before and after the trial. The style advisor did not try to get my feedback after the trial or any time in between the trial as well and neither did the style advisor compliment me on any of the products I had tried on. | BM6: Expensive products | BO6: Yes | BP6: Yes | BQ6: Yes | BR6: Asked if you were ready to purchase today^Offered information on another product to help you decide^Gave information about the price, payment options^Invited you back for more information or another demonstration or test. Gave you their business card or contact information. | BT6: Yes | BU6: Yes | BV6: Yes | BW6: No | BX6: No | BY6: Yes | BZ6: Yes | CA6: Yes | CB6: 9 | CC6: Yes | CD6: 9
A7: 11083658 | B7: 2022-10-12 | C7: 90 | D7: 100 | E7: 100 | F7: 100 | G7: 83 | H7: 88 | I7: 100 | J7: 63 | K7: 100 | L7: Chennai | M7: Tamil Nadu | N7: South | O7: IN | P7: 12:17 | Q7: 12:33 | R7: 960 | S7: 1 | T7: 1 | U7: 60 | V7: Female | W7: I was wearing dark blue jeans with a long maroon-colored top. | X7: Rizwan | Y7: Male, in his mid-late 20s, approximately 5'6' in height, fair complexion, clean-shaven, well-built with black short hair, and was wearing the Company branded orange t-shirt with plain jeans and shoes He had his name tag on. | Z7: Yes | AA7: Yes | AB7: Yes | AC7: Yes | AD7: Yes | AE7: No | AF7: Yes | AG7: Yes | AH7: Yes | AI7: The store was well-maintained and all the frames were arranged according to type and brand. There were no Cartons seen in the customer area, the store was cleaned meticulously. | AJ7: WOW! Very appealing | AL7: Smile^Eye contact^Verbal greeting within 15 seconds | AM7: Within 2 minutes | AN7: Yes | AO7: Yes | AP7: Yes | AQ7: Yes | AR7: N/A | AS7: Yes | AT7: Yes | AU7: The style advisor asked whether I was looking for sunglasses for myself or for someone else. | AV7: Yes | AW7: The style advisor mentioned about brands such as Armani, Prada, Oakley, and more. | AX7: Yes | AY7: The style advisor asked for the type of glasses I was looking for and since I wore progressive glasses, he wanted to know if I could have the lens done at an optic store. | AZ7: Yes | BA7: Yes | BB7: Yes | BC7: No | BD7: Yes | BE7: Yes | BF7: Yes | BG7: Yes | BH7: Yes | BI7: Yes | BJ7: No | BK7: The style advisor recommended shell frames across different brands and showed me Ray-Ban aviators, Prada, D&G, Oakley, Bvlgari, and Oakley. | BL7: The overall trial experience was good. The style advisor recommended shell frames across different brands and showed me Ray-Ban aviators, Prada, D&G, Oakley, Bvlgari, and Oakley. Some of them were oversized; he also mentioned that customizing of the power lenses was not done at the store. The style advisor was very patient and handled all my queries well. I had asked for magnetic frames as well, they had only one from Armani which he showed to me. It was a set of 2 different colored outer frames, red and blue to put on the mainframe. Since the brands were all international brands, he informed me that they were expensive and that they came with an international warranty of 2 years. An additional product was not shown. | BM7: Expensive products | BO7: Yes | BP7: Yes | BQ7: Yes | BR7: Gave information about the price, payment options | BT7: Yes | BU7: Yes | BV7: No | BW7: No | BX7: No | BY7: No | BZ7: Yes | CA7: Yes | CB7: 8 | CC7: Yes | CD7: 8
A8: 11083773 | B8: 2022-10-06 | C8: 36 | D8: 78 | E8: 90 | F8: 0 | G8: 0 | H8: 0 | I8: 0 | J8: 25 | K8: 0 | L8: Mumbai | M8: Maharashtra | N8: West | O8: IN | P8: 17:45 | Q8: 18:00 | R8: 900 | S8: 1 | T8: 1 | U8: 32 | V8: Male | W8: I was wearing formals during my visit. | X8: Mohsin | Y8: Male, approximately 5'5' in height, fair complexion, black hair, was wearing the Company branded t-shirt, plain jeans, shoes, and was not clean shaven. | Z8: Yes | AA8: Yes | AB8: Yes | AC8: No | AD8: No | AE8: No | AF8: Yes | AG8: Yes | AH8: Yes | AI8: The store was clean and well-lit. | AJ8: Good, looks interesting | AL8: Smile^Eye contact^Verbal greeting within 15 seconds | AM8: Within 2 minutes | AN8: Yes | AO8: Yes | AP8: Yes | AQ8: Yes | AR8: No | AS8: No | AT8: No | AU8: The style advisor did not ask me any questions specific to my requirements. | AV8: No | AW8: The product features were not discussed. | AX8: No | AZ8: No | BA8: No | BB8: No | BC8: No | BD8: No | BE8: No | BF8: No | BG8: No | BH8: No | BI8: No | BJ8: No | BK8: The style advisor was just presenting the product. When I asked him if they could customize glasses for my eye power, he said they would not do it. | BL8: The style advisor was unable to solve my questions like customizing eye frames according to my eye power and anti-reflection glasses. | BM8: Discount on the first pair | BO8: No | BP8: No | BQ8: No | BR8: None of the above | BT8: No | BU8: No | BV8: No | BW8: No | BX8: Yes | BY8: No | BZ8: Yes | CA8: Yes | CB8: 5 | CC8: No | CD8: 2
A9: 11083777 | B9: 2022-10-11 | C9: 34 | D9: 78 | E9: 60 | F9: 40 | G9: 0 | H9: 0 | I9: 33 | J9: 13 | K9: 0 | L9: Mumbai | M9: Maharashtra | N9: West | O9: IN | P9: 12:00 | Q9: 12:15 | R9: 900 | S9: 2 | T9: 1 | U9: 32 | V9: Male | W9: I was wearing a black t-shirt with blue colored denim. | X9: Keneth | Y9: Male, approximately 5'9' in height, fair complexion, black hair, clean-shaven, and was wearing a jacket with shoes. | Z9: Yes | AA9: Yes | AB9: Yes | AC9: No | AD9: No | AE9: No | AF9: Yes | AG9: Yes | AH9: Yes | AI9: The store was clean and well-lit. The store did not have a digital screen and there were no cartons lying around the store. Music was not played at the store. | AJ9: Good, looks interesting | AL9: Verbal greeting within 15 seconds | AM9: Within 2 minutes | AN9: Yes | AO9: Yes | AP9: Yes | AQ9: No | AR9: No | AS9: Yes | AT9: No | AU9: The style advisor asked how he could assist me. | AV9: No | AW9: Product features were not discussed. | AX9: No | AZ9: No | BA9: No | BB9: No | BC9: No | BD9: No | BE9: No | BF9: No | BG9: No | BH9: No | BI9: No | BJ9: No | BK9: The style advisor did not recommend anything. | BL9: The style advisor was quite hostile throughout the trial trying to belittle me. The style advisor's behavior was equal to that of a fired employee or even worse than that. | BM9: Discount on the first pair | BO9: No | BP9: Yes | BQ9: No | BR9: None of the above | BT9: No | BU9: No | BV9: No | BW9: No | BX9: No | BY9: No | BZ9: No | CA9: No | CB9: 1 | CC9: No | CD9: 1
A10: 11083778 | B10: 2022-10-12 | C10: 74 | D10: 78 | E10: 90 | F10: 40 | G10: 50 | H10: 100 | I10: 100 | J10: 50 | K10: 100 | L10: Mumbai | M10: Maharashtra | N10: West | O10: IN | P10: 12:00 | Q10: 12:15 | R10: 900 | S10: 1 | T10: 1 | U10: 32 | V10: Male | W10: I was wearing a t-shirt with jeans. | X10: Rakesh | Y10: Male, approximately 5'2' in height, fair complexion with black hair, not shaven, and was wearing the Company branded t-shirt with plain jeans and shoes. | Z10: Yes | AA10: Yes | AB10: Yes | AC10: No | AD10: No | AE10: No | AF10: Yes | AG10: Yes | AH10: Yes | AI10: The store was clean and well-lit. It did not have a digital screen and there was no music playing at the store. | AJ10: Good, looks interesting | AL10: Smile^Eye contact^Verbal greeting within 15 seconds | AM10: Within 2 minutes | AN10: Yes | AO10: Yes | AP10: Yes | AQ10: Yes | AR10: No | AS10: No | AT10: Yes | AU10: The style advisor asked how he could help with my requirements. | AV10: No | AW10: The style advisor mentioned the names of the brand only. | AX10: Yes | AY10: The style advisor asked what type of frames I would be interested in. | AZ10: Yes | BA10: No | BB10: Yes | BC10: No | BD10: Yes | BE10: Yes | BF10: Yes | BG10: Yes | BH10: Yes | BI10: Yes | BJ10: Yes | BK10: The style advisor recommended sunglasses in different frames suitable for my facial structure. | BL10: The style advisor was energetic in their approach and was eager to assist; he presented a variety of frames to try however, more information on the brands could have been provided while presenting the products for trial. The style advisor made use of the styling tray and the micro-fiber cloth to clean the glasses before and even after the trial. | BM10: Discount on the first pair | BO10: Yes | BP10: Yes | BQ10: Yes | BR10: Summarized your needs and matched them to the product recommended | BT10: Yes | BU10: No | BV10: No | BW10: No | BX10: No | BY10: No | BZ10: Yes | CA10: Yes | CB10: 8 | CC10: Yes | CD10: 8
A11: 11083780 | B11: 2022-10-08 | C11: 74 | D11: 78 | E11: 90 | F11: 60 | G11: 17 | H11: 100 | I11: 100 | J11: 63 | K11: 100 | L11: Mumbai | M11: Maharashtra | N11: West | O11: IN | P11: 17:30 | Q11: 17:45 | R11: 900 | S11: 3 | T11: 0 | U11: 32 | V11: Male | W11: T-shirt and jeans | X11: Rashid | Y11: Male, approximately 5'5' in height, fair complexion, black hair, and wore the Company branded t-shirt with plain jeans and shoes. Did not shave. | Z11: Yes | AA11: Yes | AB11: Yes | AC11: No | AD11: No | AE11: No | AF11: Yes | AG11: Yes | AH11: Yes | AI11: The store was clean and well-lit. | AJ11: Good, looks interesting | AL11: Smile^Eye contact^Verbal greeting within 15 seconds | AM11: Within 2 minutes | AN11: Yes | AO11: Yes | AP11: Yes | AQ11: Yes | AR11: No | AS11: Yes | AT11: Yes | AU11: The style advisor asked me how he could help me. | AV11: No | AW11: The product features were not discussed. | AX11: No | AZ11: Yes | BA11: No | BB11: No | BC11: No | BD11: Yes | BE11: Yes | BF11: Yes | BG11: Yes | BH11: Yes | BI11: Yes | BJ11: Yes | BK11: The Style Advisor gave me additional sunglass pairs when I was checking the frames. | BL11: The Style Advisor was energetic in his approach and eager to assist. More information on brands could be provided when he presented the products. | BM11: Discount on the first pair | BO11: Yes | BP11: Yes | BQ11: Yes | BR11: Gave information about the price, payment options | BT11: Yes | BU11: No | BV11: Yes | BW11: No | BX11: No | BY11: No | BZ11: Yes | CA11: Yes | CB11: 8 | CC11: Yes | CD11: 8
A12: 11083781 | B12: 2022-10-12 | C12: 86 | D12: 78 | E12: 80 | F12: 100 | G12: 100 | H12: 100 | I12: 100 | J12: 63 | K12: 100 | L12: Mumbai | M12: Maharashtra | N12: West | O12: IN | P12: 13:34 | Q12: 14:00 | R12: 1560 | S12: 2 | T12: 1 | U12: 32 | V12: Male | W12: I was wearing a t-shirt with denims. | X12: Gaurav | Y12: Male, approximately 5'5' in height, brown complexion, black hair, was wearing a shirt with plain jeans, shoes, and no shave. | Z12: Yes | AA12: Yes | AB12: Yes | AC12: No | AD12: No | AE12: No | AF12: Yes | AG12: Yes | AH12: Yes | AI12: The store was clean and well-lit. The store did not have a digital screen. Music was not played at the store and there were no cartons lying around. | AJ12: Good, looks interesting | AL12: Eye contact^Verbal greeting within 15 seconds | AM12: Within 2 minutes | AN12: Yes | AO12: Yes | AP12: Yes | AQ12: Yes | AR12: No | AS12: Yes | AT12: Yes | AU12: The style advisor asked how he could help me with my requirements. | AV12: Yes | AW12: The style advisor informed me that they had the manufacturing license for Ray-ban. | AX12: Yes | AY12: The style advisor asked if I had any particular product in mind or was looking for from the specific brand. | AZ12: Yes | BA12: Yes | BB12: Yes | BC12: Yes | BD12: Yes | BE12: Yes | BF12: Yes | BG12: Yes | BH12: Yes | BI12: Yes | BJ12: Yes | BK12: The style advisor recommended sunglasses in different frames that would be suitable for my facial structure. | BL12: The style advisor gave additional sunglass pairs for the trial along with the ones I had requested. During the trial, the style advisor used the styling tray and even made sure to clean the glasses with the micro-fiber cloth before handing them to me for the trial. During the trial process, the style advisor even provided proper feedback for each glass. | BM12: Expensive products | BO12: Yes | BP12: Yes | BQ12: Yes | BR12: Summarized your needs and matched them to the product recommended | BT12: Yes | BU12: Yes | BV12: No | BW12: No | BX12: No | BY12: No | BZ12: Yes | CA12: Yes | CB12: 8 | CC12: Yes | CD12: 8
A13: 11083783 | B13: 2022-10-11 | C13: 70 | D13: 78 | E13: 60 | F13: 100 | G13: 50 | H13: 88 | I13: 100 | J13: 38 | K13: 100 | L13: Mumbai | M13: Maharashtra | N13: West | O13: IN | P13: 14:25 | Q13: 14:40 | R13: 900 | S13: 2 | T13: 1 | U13: 32 | V13: Male | W13: I was wearing a t-shirt with denims. | X13: Kiran | Y13: Male, approximately 5'6' in height, fair complexion, black hair, and was wearing the Company brand t-shirt, plain jeans, shoes, and no shave. | Z13: Yes | AA13: Yes | AB13: Yes | AC13: No | AD13: No | AE13: No | AF13: Yes | AG13: Yes | AH13: Yes | AI13: The store was clean and well-lit as the area manager was present in the store. The store did not have a digital screen and did not have any music playing inside. There were no cartons lying around. | AJ13: Good, looks interesting | AL13: Verbal greeting within 15 seconds | AM13: Within 2 minutes | AN13: Yes | AO13: Yes | AP13: Yes | AQ13: No | AR13: No | AS13: Yes | AT13: Yes | AU13: The style advisor asked how he could help me. | AV13: Yes | AW13: The style advisor informed me about the Ferrari and Ray-ban collaboration. | AX13: Yes | AY13: The style advisor asked about my specific requirements. | AZ13: Yes | BA13: No | BB13: Yes | BC13: No | BD13: Yes | BE13: Yes | BF13: Yes | BG13: Yes | BH13: Yes | BI13: Yes | BJ13: No | BK13: The product details were not mentioned. The current season's inspiration was not shared. | BL13: Since the area manager was present, there was no issue with the trial. The style advisor was energetic and eager to assist. The style advisor gave me multiple sunglasses for the trial while I checked the frames. The style advisor could work on providing more information about the products when presenting them for the trial. The style advisor used the styling tray and cleaned the glasses before and after the trial as well. | BM13: Discount on the first pair | BO13: Yes | BP13: Yes | BQ13: Yes | BR13: Summarized your needs and matched them to the product recommended | BT13: Yes | BU13: Yes | BV13: No | BW13: No | BX13: No | BY13: No | BZ13: No | CA13: No | CB13: 8 | CC13: Yes | CD13: 8
A14: 11083867 | B14: 2022-10-08 | C14: 84 | D14: 89 | E14: 89 | F14: 80 | G14: 83 | H14: 100 | I14: 100 | J14: 50 | K14: 100 | L14: Bangalore | M14: Karnataka | N14: South | O14: IN | P14: 16:39 | Q14: 17:04 | R14: 1500 | S14: 2 | T14: 3 | U14: 40 | V14: Male | W14: I was wearing a black jeans with red and blue shorts. | X14: Sanit Saji | Y14: Male, tall in height, fair complexion, clean-shaven, was wearing an orange t-shirt, thin build. | Z14: Yes | AA14: Yes | AB14: Yes | AC14: No | AD14: Yes | AE14: No | AF14: Yes | AG14: Yes | AH14: Yes | AI14: It was easy to locate the store. The exterior and the interior of the store were well maintained and the signage of the store was visible even from a certain distance. It was well-lit and the exterior was neat and clean. Overall, the store looked very appealing. There was no music playing in the store and also there was a digital screen being played behind the cash counter area. There were no unwanted and unattended cartons seen at the store. The sunglass merchandise was displayed and organized very well. There was enough space to move and look around the displayed merchandise. The product was arranged according to the brand and the arrangement was also done according to the pattern. | AJ14: WOW! Very appealing | AL14: Smile^Eye contact^Verbal greeting within 15 seconds | AM14: Within 2 minutes | AN14: Yes | AO14: Yes | AP14: Yes | AQ14: No | AR14: N/A | AS14: Yes | AT14: Yes | AU14: The style advisor asked me about the style of frame I would prefer and whether the purchase was for formal or casual wear. The style advisor also inquired if I had any budget constraints and asked about my preference for the glass shades. | AV14: Yes | AW14: No additional remarks were made. | AX14: No | AZ14: Yes | BA14: Yes | BB14: Yes | BC14: No | BD14: Yes | BE14: Yes | BF14: Yes | BG14: Yes | BH14: Yes | BI14: Yes | BJ14: Yes | BK14: The style advisor recommended the Armani glasses in a blue shade with silver rims and a black shade with an adjustable nose bridge. | BL14: The style advisor encouraged me to touch and try the shortlisted products. The style advisor even wiped them with the micro-fiber cloth before handing the products to me. The Armani glass was in size XL which was a little loose but the style advisor assured me that the nose pads were adjustable. The style advisor then proceeded to show me the Ray-Ban aviator glasses which the style advisor suggested that I should try as they were the best suited for my facial structure. | BM14: Expensive products | BO14: Yes | BP14: Yes | BQ14: Yes | BR14: Offered information on another product to help you decide^Summarized your needs and matched them to the product recommended | BT14: Yes | BU14: Yes | BV14: No | BW14: No | BX14: No | BY14: No | BZ14: Yes | CA14: No | CB14: 9 | CC14: Yes | CD14: 9
A15: 11083988 | B15: 2022-10-15 | C15: 78 | D15: 78 | E15: 100 | F15: 80 | G15: 83 | H15: 50 | I15: 100 | J15: 63 | K15: 100 | L15: Hyderabad | M15: Telangana | N15: South | O15: IN | P15: 17:41 | Q15: 18:15 | R15: 2040 | S15: 2 | T15: 1 | U15: 28 | V15: Male | W15: I was wearing a t-shirt with jeans. | X15: Asif | Y15: Male, approximately 5'6' in height, thin and medium build with a fair complexion, black hair, and a beard. He must have been around 28years old. He was wearing the Company branded t-shirt with plain jeans and he did not have any spectacles on. | Z15: Yes | AA15: Yes | AB15: Yes | AC15: No | AD15: No | AE15: No | AF15: Yes | AG15: Yes | AH15: Yes | AI15: The store was small but the arrangement of the furniture and merchandise was set in a way that made it possible to roam around the store freely. There was no music playing and the digital screen at the entrance was not operational. | AJ15: Good, looks interesting | AL15: Smile^Eye contact^Verbal greeting within 15 seconds | AM15: Within 2 minutes | AN15: Yes | AO15: Yes | AP15: Yes | AQ15: Yes | AR15: N/A | AS15: Yes | AT15: Yes | AU15: The style advisor did not ask any questions, he simply answered to the ones I asked | AV15: Yes | AW15: The style advisor was proactive and tried to convince me to buy the sunglasses. | AX15: No | AZ15: Yes | BA15: Yes | BB15: Yes | BC15: No | BD15: Yes | BE15: Yes | BF15: Yes | BG15: No | BH15: No | BI15: No | BJ15: No | BK15: No additional products were recommended to me. | BL15: I tried around 4 to 5 spectacles, which the style advisor did not clean before the trial. I had asked him which one of the spectacles suited me the best, to which he recommended that the Ray-Ban spectacles were the best for my facial structure. | BM15: Discount on the first pair | BO15: Yes | BP15: Yes | BQ15: Yes | BR15: Offered information on another product to help you decide^Gave information about the price, payment options^Other (please specify) | BS15: The style advisor gave the details of discounts and offers. | BT15: Yes | BU15: Yes | BV15: No | BW15: No | BX15: No | BY15: No | BZ15: Yes | CA15: Yes | CB15: 9 | CC15: Yes | CD15: 8
A16: 11084277 | B16: 2022-10-08 | C16: 61 | D16: 78 | E16: 67 | F16: 60 | G16: 83 | H16: 38 | I16: 67 | J16: 38 | K16: 100 | L16: Pune | M16: Maharashtra | N16: West | O16: IN | P16: 14:23 | Q16: 14:51 | R16: 1680 | S16: 3 | T16: 1 | U16: 31 | V16: Male | W16: I was wearing a black t-shirt with blue jeans. | X16: Yasin Kaif | Y16: Male, approximately 5'7'' in height, fair complexion, and was wearing the Company branded t-shirt. | Z16: Yes | AA16: Yes | AB16: Yes | AC16: No | AD16: No | AE16: No | AF16: Yes | AG16: Yes | AH16: Yes | AI16: The Sunglass Hut store was present on the ground floor of the Westend Mall. The signage was well-lit and hence it was visible from a long distance. The entrance had a standee that mentioned the ongoing offer which was a 25% off on the 2nd pair. The exterior of the store façade was all glass and smudge-free. I did not observe any kind of litter in the store. The store looked well-maintained and clean. All the products were arranged according to their brand. However, I was not sure whether they were arranged according to the frame or not. | AJ16: Good, looks interesting | AL16: Smile^Verbal greeting within 15 seconds | AM16: Within 2 minutes | AN16: Yes | AO16: No | AP16: Yes | AQ16: No | AR16: N/A | AS16: Yes | AT16: Yes | AU16: There were no questions asked by the style advisor. | AV16: No | AW16: The style advisor informed us about the 2-year warranty that the product would come with 6 months of replacement coverage, and also informed us that the warranty was applicable across the globe. | AX16: No | AZ16: Yes | BA16: Yes | BB16: Yes | BC16: No | BD16: Yes | BE16: No | BF16: No | BG16: Yes | BH16: Yes | BI16: No | BJ16: No | BK16: The style advisor recommended two products. One was from Versace and another one was from Micheal Kors. Regarding the Versace shades, the style advisor said that they were made of specially engineered material that made them lightweight. Also, that was the reason for it being expensive. Moreover, they were offering an international warranty on it too. It was manufactured by Luxottica. Not many details were given for the Michael Kors one since we were interested in them. | BL16: Since there were no questions from the style advisor, we proactively mentioned that we were looking for cat-eyed frames. After this, the style advisor recommended us multiple products, including products from the brands like Michael Kors and Versace. There were no budget or style-related questions from the style advisor as well. The style advisor encouraged us to touch/feel and try the products only after we had asked if we could try them on. He did not proactively initiate it. The style advisor also told us about the materials that were used in the products and their durability as well. | BM16: Expensive products | BO16: Yes | BP16: Yes | BQ16: No | BR16: Gave information about the price, payment options | BT16: Yes | BU16: Yes | BV16: No | BW16: No | BX16: No | BY16: No | BZ16: No | CA16: No | CB16: 8 | CC16: Yes | CD16: 8
A17: 11084762 | B17: 2022-10-06 | C17: 78 | D17: 89 | E17: 100 | F17: 80 | G17: 50 | H17: 88 | I17: 67 | J17: 50 | K17: 100 | L17: Mumbai | M17: Maharashtra | N17: West | O17: IN | P17: 16:52 | Q17: 17:30 | R17: 2280 | S17: 02 | T17: 1 | U17: 57 | V17: Male | W17: I was wearing a red and black check shirt, pants, shoes, and spectacles. | X17: Bablu | Y17: Male, approximately 5'6' in height, fair complexion, black hair, was wearing the Company branded t-shirt, plain jeans, shoes, clean shaven and hairstyle done. | Z17: Yes | AA17: Yes | AB17: Yes | AC17: Yes | AD17: No | AE17: No | AF17: Yes | AG17: Yes | AH17: Yes | AI17: The store was neat and clean during the visit. The exterior signage was clean and shiny. Overall, the various brands of sunglasses were displayed beautifully brand-wise. | AJ17: Good, looks interesting | AL17: Smile^Eye contact^Verbal greeting within 15 seconds | AM17: Within 2 minutes | AN17: Yes | AO17: Yes | AP17: Yes | AQ17: Yes | AR17: N/A | AS17: Yes | AT17: Yes | AU17: The style advisor asked me what I was looking for. | AV17: Yes | AW17: No additional remarks were made. | AX17: No | AZ17: Yes | BA17: No | BB17: Yes | BC17: No | BD17: Yes | BE17: Yes | BF17: Yes | BG17: No | BH17: Yes | BI17: Yes | BJ17: Yes | BK17: The style advisor mainly recommended Prada sunglass in different colors and shapes. He showed me the products and asked for a trial of the sunglasses and I did the same. The Prada sunglass was gray and dark in color. The RayBan sunglass was light grey. | BL17: The style advisor assisted me properly during the visit. He encouraged me to try on different sunglasses during the visit and I made the trial of sunglasses accordingly. The focused brand was Prada sunglasses from the style advisor's side. As per my discussion, the style advisor also showed me RayBan sunglasses. Overall, my experience was good. | BM17: Expensive products | BO17: Yes | BP17: No | BQ17: Yes | BR17: Offered information on another product to help you decide^Gave information about the price, payment options | BT17: Yes | BU17: No | BV17: No | BW17: Yes | BX17: No | BY17: No | BZ17: Yes | CA17: No | CB17: 8 | CC17: Yes | CD17: 8
A18: 11084763 | B18: 2022-10-11 | C18: 89 | D18: 89 | E18: 100 | F18: 80 | G18: 83 | H18: 88 | I18: 67 | J18: 100 | K18: 100 | L18: Mumbai | M18: Maharashtra | N18: West | O18: IN | P18: 17:24 | Q18: 18:04 | R18: 2400 | S18: 2 | T18: 1 | U18: 57 | V18: Male | W18: I was wearing a colorful shirt with pants and shoes. | X18: Nagraj | Y18: Male, approximately 5'5' in height, light fair complexion, black hair, and was wearing the Sunglass branded t-shirt, pants, and shoes, clean-shaven, with a proper hairstyle, style advisor had an ID card. | Z18: Yes | AA18: Yes | AB18: Yes | AC18: No | AD18: Yes | AE18: No | AF18: Yes | AG18: Yes | AH18: Yes | AI18: The store looked attractive and appealing to the eyes. The store was spacious enough to move freely. There was no music being played and no cartons were lying around. | AJ18: Good, looks interesting | AL18: Smile^Eye contact^Verbal greeting within 15 seconds | AM18: Within 2 minutes | AN18: Yes | AO18: Yes | AP18: Yes | AQ18: Yes | AR18: N/A | AS18: Yes | AT18: Yes | AU18: The Style Advisor asked if I was looking for sunglasses for someone in particular. | AV18: Yes | AW18: The Style Advisor mentioned that the sunglasses were of good quality. | AX18: No | AZ18: Yes | BA18: Yes | BB18: Yes | BC18: No | BD18: Yes | BE18: Yes | BF18: Yes | BG18: Yes | BH18: Yes | BI18: Yes | BJ18: No | BK18: Sunglasses from Ray-Ban and Prada were recommended. | BL18: The overall trial experience for the sunglasses was very nice and I was happy with it. The style advisor offered Ray-ban sunglasses for the trial and mentioned that they were the perfect high-quality UV-protected sunglasses that provided clarity as well. The style advisor showed me different sunglasses in colors such as wine red, brown, green, etc in metal as well as the fiber material. The next item, the style advisor offered for the trial was from the luxury brand, Prada, it had a rich feel to it. The glasses looked good when I checked in the mirror at the store. An additional product to purchase that would complete the look was not recommended to me. The brand story was not told to me. The styling tray was used and the glasses were cleaned before and after the trial. | BM18: Discount on the first pair | BO18: No | BP18: Yes | BQ18: Yes | BR18: Asked if you were ready to purchase today^Gave information about the price, payment options^Invited you back for more information or another demonstration or test. Gave you their business card or contact information. | BT18: Yes | BU18: Yes | BV18: Yes | BW18: Yes | BX18: No | BY18: N/A | BZ18: Yes | CA18: N/A | CB18: 8 | CC18: Yes | CD18: 8
A19: 11084781 | B19: 2022-10-13 | C19: 65 | D19: 89 | E19: 89 | F19: 80 | G19: 50 | H19: 25 | I19: 33 | J19: 63 | K19: 100 | L19: Cochin | M19: Kerala | N19: South | O19: IN | P19: 15:05 | Q19: 15:30 | R19: 1500 | S19: 2 | T19: 1 | U19: 42 | V19: Male | W19: I was wearing a formal shirt and trousers. | X19: Ashish | Y19: Male approximately 5'11'' in height, wore spectacles, fair complexion with black hair, and was wearing a casual shirt with blue jeans. | Z19: Yes | AA19: Yes | AB19: Yes | AC19: No | AD19: Yes | AE19: No | AF19: Yes | AG19: Yes | AH19: Yes | AI19: The store signage was clean and well-maintained. The store was cluttered-free, and the entrance and fixtures were all in good condition. There was no music playing but the digital screen at the entrance worked well and all the merchandise was arranged and displayed properly in the drawers and shelves. | AJ19: Good, looks interesting | AL19: Smile^Eye contact^Verbal greeting within 15 seconds | AM19: Within 2 minutes | AN19: Yes | AO19: Yes | AP19: Yes | AQ19: No | AR19: N/A | AS19: Yes | AT19: Yes | AU19: The style advisor asked about the particular brand I was looking for. | AV19: Yes | AW19: While suggesting the products, the style advisor mentioned only the brand names. | AX19: No | AZ19: Yes | BA19: Yes | BB19: No | BC19: No | BD19: Yes | BE19: No | BF19: No | BG19: No | BH19: No | BI19: No | BJ19: Yes | BK19: Since the aviators from Ray-Ban that I mentioned were out of stock, the style advisor recommended aviator glasses from other brands. | BL19: The style advisor had me try on the glasses that I had shown an interest in. During the trial, he did not use the styling tray or the micro-fiber cloth to clean the glasses before or even after the trial. The style advisor did not give any suggestions or compliments during the trial session. I was not offered compliments. Appropriate recommendations were not offered as per my facial characteristics. | BM19: Discount on the first pair | BO19: No | BP19: No | BQ19: Yes | BR19: Offered information on another product to help you decide^Gave information about the price, payment options | BT19: Yes | BU19: Yes | BV19: No | BW19: No | BX19: No | BY19: Yes | BZ19: Yes | CA19: No | CB19: 6 | CC19: Yes | CD19: 6
A20: 11084784 | B20: 2022-10-06 | C20: 76 | D20: 89 | E20: 89 | F20: 80 | G20: 50 | H20: 75 | I20: 100 | J20: 63 | K20: 0 | L20: Ludhiana | M20: Punjab | N20: North | O20: IN | P20: 12:45 | Q20: 13:10 | R20: 1500 | S20: 1 | T20: 1 | U20: 43 | V20: Male | W20: I was wearing a off white shirt with brown trousers. | X20: Sunil | Y20: Male, approximately 5'7' in height, fair complexion, black hair, wore no spectacles, was wearing the Company branded t-shirt, plain jeans, shoes, was clean shaven and hairstyle done. | Z20: Yes | AA20: Yes | AB20: Yes | AC20: Yes | AD20: No | AE20: No | AF20: Yes | AG20: Yes | AH20: Yes | AI20: The exterior signage was clean and well lit. All the fixtures and other tangibles were in good condition. The merchandise was displayed and arranged well. | AJ20: Good, looks interesting | AL20: Smile^Eye contact^Verbal greeting within 15 seconds | AM20: Within 2 minutes | AN20: Yes | AO20: Yes | AP20: Yes | AQ20: No | AR20: N/A | AS20: Yes | AT20: Yes | AU20: The style advisor asked me about my brand choice and colour. | AV20: Yes | AW20: None | AX20: No | AZ20: Yes | BA20: No | BB20: Yes | BC20: No | BD20: Yes | BE20: No | BF20: Yes | BG20: Yes | BH20: Yes | BI20: No | BJ20: Yes | BK20: The style advisor recommended goggles in case of different types of shapes. | BL20: My trial experience was good because the style advisor offered me proactively different brands and color goggles for the trial. | BM20: Discount on the first pair | BO20: Yes | BP20: Yes | BQ20: Yes | BR20: Asked if you were ready to purchase today^Summarized your needs and matched them to the product recommended^Asked if you had any further questions^Gave information about the price, payment options | BT20: Yes | BU20: Yes | BV20: No | BW20: No | BX20: No | BY20: Yes | BZ20: Yes | CA20: No | CB20: 8 | CC20: No | CD20: 8
A21: 11084789 | B21: 2022-10-10 | C21: 82 | D21: 89 | E21: 90 | F21: 80 | G21: 50 | H21: 88 | I21: 100 | J21: 75 | K21: 100 | L21: Amritsar | M21: Punjab | N21: North | O21: IN | P21: 12:55 | Q21: 13:16 | R21: 1260 | S21: 3 | T21: 1 | U21: 43 | V21: Male | W21: I was wearing a navy pant and shirt. | X21: Kamal | Y21: Male, approximately 5'7'' in height, fair complexion, black hair, wore no spectacles, was wearing the Company branded uniform with plain jeans and shoes, clean-shaven, the hairstyle was done in a proper manner. | Z21: Yes | AA21: Yes | AB21: Yes | AC21: Yes | AD21: No | AE21: No | AF21: Yes | AG21: Yes | AH21: Yes | AI21: The store ambiance was good and there were no cartons lying around. The store did not have a digital screen. | AJ21: Good, looks interesting | AL21: Smile^Eye contact^Verbal greeting within 15 seconds | AM21: Within 2 minutes | AN21: Yes | AO21: Yes | AP21: Yes | AQ21: Yes | AR21: No | AS21: Yes | AT21: Yes | AU21: The style advisor asked about my choice of brands, style and my glass preference for the purchase. | AV21: Yes | AW21: The style advisor showed me goggles from the Ray-ban, Emporio Armani, D&G, and Prada brands in polaroid and UV glasses and in different types of shapes. | AX21: No | AZ21: Yes | BA21: No | BB21: Yes | BC21: No | BD21: Yes | BE21: Yes | BF21: Yes | BG21: Yes | BH21: Yes | BI21: No | BJ21: Yes | BK21: The style advisor recommended the goggles cleaning kits in different types of shapes. | BL21: My overall trial experience was good. The style advisor encouraged me to touch/feel and try the products from the different brands. The style advisor offered appropriate recommendations for goggles as per my facial structure but did not try to get my feedback on them. The style advisor used the styling tray and microfiber cloth during the trial and demonstration. The style advisor did not try to get my feedback. | BM21: Expensive products | BO21: Yes | BP21: Yes | BQ21: Yes | BR21: Offered information on another product to help you decide^Gave information about the price, payment options^Invited you back for more information or another demonstration or test. Gave you their business card or contact information. | BT21: Yes | BU21: Yes | BV21: No | BW21: No | BX21: No | BY21: Yes | BZ21: Yes | CA21: Yes | CB21: 9 | CC21: Yes | CD21: 9
A22: 11084792 | B22: 2022-10-10 | C22: 88 | D22: 89 | E22: 100 | F22: 100 | G22: 83 | H22: 88 | I22: 100 | J22: 63 | K22: 100 | L22: Amritsar | M22: Punjab | N22: North | O22: IN | P22: 14:10 | Q22: 14:35 | R22: 1500 | S22: 3 | T22: 1 | U22: 40 | V22: Male | W22: I was wearing a blue trouser and shirt. | X22: Neeraj | Y22: Male, approximately 5'7'' in height, wheatish complexion, black hair, did not wear spectacles, was wearing the Company branded shirt with plain jeans and shoes, had no beard, and the hairstyle was done in a proper manner. | Z22: Yes | AA22: Yes | AB22: Yes | AC22: Yes | AD22: No | AE22: No | AF22: Yes | AG22: Yes | AH22: Yes | AI22: The store did not have a digital screen. The exterior signage was clean and well-lit. All the fixtures and other tangibles were in good condition. The merchandise was displayed and arranged well. | AJ22: Good, looks interesting | AL22: Smile^Eye contact^Verbal greeting within 15 seconds | AM22: Within 2 minutes | AN22: Yes | AO22: Yes | AP22: Yes | AQ22: Yes | AR22: Yes | AS22: Yes | AT22: Yes | AU22: The style advisor asked what brands, and styles I was interested in and my preference for the goggles. | AV22: Yes | AW22: No additional remarks were made. | AX22: Yes | AY22: The style advisor asked the reason for my choice regarding the brand and wanted to know what type and color of glasses I would like to see for the purchase. | AZ22: Yes | BA22: Yes | BB22: Yes | BC22: No | BD22: Yes | BE22: Yes | BF22: Yes | BG22: Yes | BH22: Yes | BI22: No | BJ22: Yes | BK22: The style advisor recommended the goggle cleaning kit that came in different shapes. | BL22: My overall trial experience was very good because the style advisor encouraged me to touch and try the products. The style advisor even offered appropriate recommendations as per my facial structure but did not try to get my feedback. During the trial period, he made sure to use the styling tray and the micro-fiber cloth to clean the products as well. | BM22: Discount on the first pair | BO22: Yes | BP22: Yes | BQ22: Yes | BR22: Asked if you were ready to purchase today^Offered information on another product to help you decide^Summarized your needs and matched them to the product recommended^Gave information about the price, payment options^Invited you back for more information or another demonstration or test. Gave you their business card or contact information. | BT22: Yes | BU22: Yes | BV22: No | BW22: No | BX22: Yes | BY22: Yes | BZ22: Yes | CA22: Yes | CB22: 9 | CC22: Yes | CD22: 9
A23: 11084844 | B23: 2022-10-08 | C23: 71 | D23: 100 | E23: 67 | F23: 80 | G23: 50 | H23: 88 | I23: 0 | J23: 57 | K23: 100 | L23: Delhi | M23: Delhi (UT) | N23: North | O23: IN | P23: 17:15 | Q23: 17:43 | R23: 1680 | S23: 4 | T23: 2 | U23: 52 | V23: Male | W23: I wore a polo t-shirt along with jeans and sneakers. | X23: Sanjeev | Y23: Male, approximately 5'11' in height, fair complexion, black hair, was wearing a black and white suit, wore spectacles, and had a beard. | Z23: Yes | AA23: Yes | AB23: Yes | AC23: Yes | AD23: Yes | AE23: No | AF23: Yes | AG23: Yes | AH23: Yes | AI23: The exterior, signage, and windows of the store were well-maintained and properly set. It had a good appealing look. There was light music playing in the store. There were no cartons or clutter lying in the store. All the merchandise was completely set with proper brand tagging and the store had a wide entrance making it very easy to explore the store. | AJ23: WOW! Very appealing | AL23: Eye contact | AM23: Within 2 minutes | AN23: Yes | AO23: Yes | AP23: Yes | AQ23: No | AR23: N/A | AS23: Yes | AT23: Yes | AU23: I asked about the style of the sunglasses, colour and the shade of the lens. | AV23: Yes | AW23: Only the brand names were informed. | AX23: No | AZ23: Yes | BA23: No | BB23: Yes | BC23: No | BD23: Yes | BE23: Yes | BF23: Yes | BG23: Yes | BH23: Yes | BI23: Yes | BJ23: No | BK23: The products recommended were Ray-Ban aviators, Burberry wayfarer, and Dolce & Gabbana wayfarer. | BL23: Based on my face cut, the style advisor suggested Ray-Ban and also mentioned that I would get the best money value if I would go for Aviators, especially with the wide variety of options that were available. He showed me 2 of them, cleaned them, and offered to try them. He also cleaned the Burberry and D&C glasses and offered to try them as well. He complimented me that Ray Ban looked the best on me and asked if I felt the same. He used the microfiber cloth and tray during the interaction. | BM23: Discount on the first pair | BO23: No | BP23: No | BQ23: No | BR23: Asked if you were ready to purchase today^Gave information about the price, payment options | BT23: Yes | BU23: No | BV23: No | BW23: No | BX23: No | BY23: N/A | BZ23: Yes | CA23: Yes | CB23: 8 | CC23: Yes | CD23: 8
